<?xml version="1.0" encoding="utf-8"?>
<!-- =================================================================================== -->
<!-- |    This document was autogenerated by xacro from /home/nope/catkin_ws/src/vrx/wamv_gazebo/urdf/wamv_gazebo.urdf.xacro | -->
<!-- |    EDITING THIS FILE BY HAND IS NOT RECOMMENDED                                 | -->
<!-- =================================================================================== -->
<!-- Basic WAM-V with gazebo plugins for dynamics -->
<robot name="WAM-V" xmlns:xacro="http://ros.org/wiki/xacro">
  <link name="left_battery_link">
    <visual name="left_battery_visual">
      <origin rpy="0 0 0" xyz="0 -0.52 -0.2"/>
      <geometry>
        <mesh filename="package://vrx_gazebo/models/battery/mesh/battery.dae" scale="0.5 0.5 0.5"/>
      </geometry>
    </visual>
    <collision name="left_battery_collision">
      <origin rpy="0 0 0" xyz="0 0.05 0.05"/>
      <geometry>
        <box size=".3 .3 .15"/>
      </geometry>
    </collision>
    <inertial>
      <origin rpy=" 0 0 0" xyz="0 0 .15"/>
      <mass value="10"/>
      <inertia ixx="0.06366" ixy="0" ixz="0" iyy="0.11553" iyz="0" izz="0.128338"/>
    </inertial>
  </link>
  <joint name="left_chasis_battery_joint" type="fixed">
    <origin rpy="0 0 0" xyz="-0.8 0.2 0.6"/>
    <parent link="base_link"/>
    <child link="left_battery_link"/>
  </joint>
  <link name="right_battery_link">
    <visual name="right_battery_visual">
      <origin rpy="0 0 0" xyz="0 -0.52 -0.2"/>
      <geometry>
        <mesh filename="package://vrx_gazebo/models/battery/mesh/battery.dae" scale="0.5 0.5 0.5"/>
      </geometry>
    </visual>
    <collision name="right_battery_collision">
      <origin rpy="0 0 0" xyz="0 0.05 0.05"/>
      <geometry>
        <box size=".3 .3 .15"/>
      </geometry>
    </collision>
    <inertial>
      <origin rpy=" 0 0 0" xyz="0 0 .15"/>
      <mass value="10"/>
      <inertia ixx="0.06366" ixy="0" ixz="0" iyy="0.11553" iyz="0" izz="0.128338"/>
    </inertial>
  </link>
  <joint name="right_chasis_battery_joint" type="fixed">
    <origin rpy="0 0 0" xyz="-0.8 -0.2 0.6"/>
    <parent link="base_link"/>
    <child link="right_battery_link"/>
  </joint>
  <!-- base link -->
  <link name="base_link">
  </link>
  <gazebo>
    <plugin name="p3d_plugin_wamv" filename="libgazebo_ros_p3d.so">
      <bodyName>base_link</bodyName>
      <frameName>map</frameName>
      <updateRate>15.0</updateRate>  
      <topicName>ground_truth</topicName>
      <xyzOffset>0 0 0</xyzOffset>
      <rpyOffset>0 0 0</rpyOffset>
      <gaussianNoise>0.2</gaussianNoise>
    </plugin>
  </gazebo>
  <joint name="dummy_joint" type="fixed">
    <parent link="base_link"/>
    <child link="dummy_link"/>
  </joint>
  <link name="dummy_link">
    <visual>
      <origin rpy="1.57 0 0" xyz="-1.2 0.96 -0.0"/>
      <geometry>
        <mesh filename="package://wamv_description/models/pontoon-base/mesh/FrameAndDecking.dae" scale="0.026 0.026 0.026"/>
      </geometry>
    </visual>
    <!-- Main float -->
    <collision name="left_float">
      <origin rpy="0 1.57 0" xyz="-0.15 0.575 0.21"/>
      <geometry>
        <cylinder length="2.1" radius="0.21"/>
      </geometry>
    </collision>
    <collision name="left_front_float">
      <origin rpy="0 1.38 0" xyz="0.75 0.575 0.25"/>
      <geometry>
        <cylinder length="0.8" radius="0.17"/>
      </geometry>
    </collision>
    <!-- Beam -->
    <collision name="left_beam">
      <origin rpy="0 0 0" xyz="-0.09 0.585 0.52"/>
      <geometry>
        <box size="2.23 0.07 0.2"/>
      </geometry>
    </collision>
    <!-- Main float -->
    <collision name="right_float">
      <origin rpy="0 1.57 0" xyz="-0.15 -0.575 0.21"/>
      <geometry>
        <cylinder length="2.1" radius="0.21"/>
      </geometry>
    </collision>
    <collision name="right_front_float">
      <origin rpy="0 1.38 0" xyz="0.75 -0.575 0.25"/>
      <geometry>
        <cylinder length="0.8" radius="0.17"/>
      </geometry>
    </collision>
    <!-- Beam -->
    <collision name="right_beam">
      <origin rpy="0 0 0" xyz="-0.09 -0.585 0.52"/>
      <geometry>
        <box size="2.23 0.07 0.2"/>
      </geometry>
    </collision>
    <!-- Top base -->
    <collision name="top_base">
      <origin rpy="0 0 0" xyz="-0.09 -0 0.59"/>
      <geometry>
        <box size="2.23 1.24 0.08"/>
      </geometry>
    </collision>
    <inertial>
      <!-- From WAM-V spec sheet -->
      <mass value="160.0"/>
      <inertia ixx="49.3173" ixy="0.0" ixz="0.0" iyy="74.7699" iyz="0.0" izz="44.0125"/>
    </inertial>
  </link>
  <link name="left_engine_link">
    <visual>
      <geometry>
        <mesh filename="package://wamv_description/models/engine/mesh/engine.dae" scale="0.75 0.75 1.25"/>
      </geometry>
    </visual>
    <collision name="left_engine_vertical_axis_collision">
      <origin rpy="0 0 0" xyz="-0.16 0 -0.24"/>
      <geometry>
        <box size="0.2 0.15 0.83"/>
      </geometry>
    </collision>
    <collision name="left_engine_rear_end_collision">
      <origin rpy="0 0 0" xyz="-0.34 0 0.12"/>
      <geometry>
        <box size="0.12 0.15 0.12"/>
      </geometry>
    </collision>
    <inertial>
      <mass value="15"/>
      <inertia ixx="0.889245" ixy="0.0" ixz="0.0" iyy="0.911125" iyz="0.0" izz="0.078125"/>
    </inertial>
  </link>
  <link name="left_propeller_link">
    <visual>
      <origin rpy="0 0 0" xyz="0 0 0"/>
      <geometry>
        <mesh filename="package://wamv_description/models/propeller/mesh/propeller.dae" scale="0.75 0.75 0.75"/>
      </geometry>
    </visual>
    <collision name="left_propeller_collision">
      <origin rpy="0 1.57 0" xyz="-0.08 0 0"/>
      <geometry>
        <cylinder length="0.3" radius="0.24"/>
      </geometry>
    </collision>
    <inertial>
      <mass value="0.5"/>
      <inertia ixx="0.008545" ixy="0.0" ixz="0.0" iyy="0.008545" iyz="0.0" izz="0.0144"/>
    </inertial>
  </link>
  <joint name="left_chasis_engine_joint" type="revolute">
    <axis xyz="0 0 1"/>
    <limit effort="10" lower="-3.141592653589793" upper="3.141592653589793" velocity="10"/>
    <origin rpy="0.0 0.0 0.0" xyz="-1.15 0.585 0.6"/>
    <parent link="base_link"/>
    <child link="left_engine_link"/>
  </joint>
  <joint name="left_engine_propeller_joint" type="continuous">
    <axis rpy="0 0 0" xyz="1 0 0"/>
    <parent link="left_engine_link"/>
    <child link="left_propeller_link"/>
    <origin rpy="0 0 0" xyz="-0.2 0 -0.63"/>
    <limit effort="100" velocity="100"/>
    <dynamics damping="0.05" friction="0.05"/>
  </joint>
  <link name="right_engine_link">
    <visual>
      <geometry>
        <mesh filename="package://wamv_description/models/engine/mesh/engine.dae" scale="0.75 0.75 1.25"/>
      </geometry>
    </visual>
    <collision name="right_engine_vertical_axis_collision">
      <origin rpy="0 0 0" xyz="-0.16 0 -0.24"/>
      <geometry>
        <box size="0.2 0.15 0.83"/>
      </geometry>
    </collision>
    <collision name="right_engine_rear_end_collision">
      <origin rpy="0 0 0" xyz="-0.34 0 0.12"/>
      <geometry>
        <box size="0.12 0.15 0.12"/>
      </geometry>
    </collision>
    <inertial>
      <mass value="15"/>
      <inertia ixx="0.889245" ixy="0.0" ixz="0.0" iyy="0.911125" iyz="0.0" izz="0.078125"/>
    </inertial>
  </link>
  <link name="right_propeller_link">
    <visual>
      <origin rpy="0 0 0" xyz="0 0 0"/>
      <geometry>
        <mesh filename="package://wamv_description/models/propeller/mesh/propeller.dae" scale="0.75 0.75 0.75"/>
      </geometry>
    </visual>
    <collision name="right_propeller_collision">
      <origin rpy="0 1.57 0" xyz="-0.08 0 0"/>
      <geometry>
        <cylinder length="0.3" radius="0.24"/>
      </geometry>
    </collision>
    <inertial>
      <mass value="0.5"/>
      <inertia ixx="0.008545" ixy="0.0" ixz="0.0" iyy="0.008545" iyz="0.0" izz="0.0144"/>
    </inertial>
  </link>
  <joint name="right_chasis_engine_joint" type="revolute">
    <axis xyz="0 0 1"/>
    <limit effort="10" lower="-3.141592653589793" upper="3.141592653589793" velocity="10"/>
    <origin rpy="0.0 0.0 0.0" xyz="-1.15 -0.585 0.6"/>
    <parent link="base_link"/>
    <child link="right_engine_link"/>
  </joint>
  <joint name="right_engine_propeller_joint" type="continuous">
    <axis rpy="0 0 0" xyz="1 0 0"/>
    <parent link="right_engine_link"/>
    <child link="right_propeller_link"/>
    <origin rpy="0 0 0" xyz="-0.2 0 -0.63"/>
    <limit effort="100" velocity="100"/>
    <dynamics damping="0.05" friction="0.05"/>
  </joint>
  
  <gazebo>
    <plugin filename="libusv_gazebo_thrust_plugin.so" name="wamv_gazebo_thrust">
      <cmdTimeout>1.0</cmdTimeout>
      
      <thruster>
        <!-- Required Parameters -->
        <linkName>left_propeller_link</linkName>
        <propJointName>left_engine_propeller_joint</propJointName>
        <engineJointName>left_chasis_engine_joint</engineJointName>
        <cmdTopic>thrusters/left_thrust_cmd</cmdTopic>
        <angleTopic>thrusters/left_thrust_angle</angleTopic>
        <enableAngle>True</enableAngle>
        <!-- Optional Parameters -->
        <mappingType>1</mappingType>
        <maxCmd>1.0</maxCmd>
        <maxForceFwd>250.0</maxForceFwd>
        <maxForceRev>-100.0</maxForceRev>
        <maxAngle>1.5707963267948966</maxAngle>
      </thruster>
      <thruster>
        <!-- Required Parameters -->
        <linkName>right_propeller_link</linkName>
        <propJointName>right_engine_propeller_joint</propJointName>
        <engineJointName>right_chasis_engine_joint</engineJointName>
        <cmdTopic>thrusters/right_thrust_cmd</cmdTopic>
        <angleTopic>thrusters/right_thrust_angle</angleTopic>
        <enableAngle>True</enableAngle>
        <!-- Optional Parameters -->
        <mappingType>1</mappingType>
        <maxCmd>1.0</maxCmd>
        <maxForceFwd>250.0</maxForceFwd>
        <maxForceRev>-100.0</maxForceRev>
        <maxAngle>1.5707963267948966</maxAngle>
      </thruster>
      
    </plugin>
  </gazebo>
  <!--Gazebo Plugin for simulating WAM-V dynamics-->
  <gazebo>
    <plugin filename="libusv_gazebo_dynamics_plugin.so" name="usv_dynamics_wamv_dynamics_plugin">
      <bodyName>base_link</bodyName>
      <!-- Must be same as the ocean model!-->
      <waterLevel>0</waterLevel>
      <waterDensity>997.8</waterDensity>
      <!-- Added mass -->
      <xDotU>0.0</xDotU>
      <yDotV>0.0</yDotV>
      <nDotR>0.0</nDotR>
      <!-- Linear and quadratic drag -->
      <xU>51.3</xU>
      <xUU>72.4</xUU>
      <yV>40.0</yV>
      <yVV>0.0</yVV>
      <zW>500.0</zW>
      <kP>50.0</kP>
      <mQ>50.0</mQ>
      <nR>400.0</nR>
      <nRR>0.0</nRR>
      <!-- General dimensions -->
      <!--<boatArea>2.2</boatArea>-->
      <hullRadius>0.2286</hullRadius>
      <boatWidth>1.2192</boatWidth>
      <boatLength>2.4384</boatLength>
      <!-- Length discretization, AKA, "N" -->
      <length_n>2</length_n>
      <!-- Wave model -->
      <wave_model>ocean_waves</wave_model>
    </plugin>
  </gazebo>
  <!-- Monocular Camera -->
  <link name="front_mid_camera_link">
    <visual name="front_mid_camera_visual">
      <origin rpy="0 0 1.5707963267948966" xyz="-0.033 0 0"/>
      <geometry>
        <mesh filename="package://vrx_gazebo/models/mono_camera/mesh/mono_camera.dae"/>
      </geometry>
    </visual>
    <collision name="front_mid_camera_lens_collision">
      <origin rpy="0 1.5707963267948966 0" xyz="0.018 0 0"/>
      <geometry>
        <cylinder length="0.042" radius="0.015"/>
      </geometry>
    </collision>
    <collision name="front_mid_camera_box_collision">
      <origin rpy="0 0 0" xyz="-0.0205 0 0"/>
      <geometry>
        <box size="0.036 0.03 0.03"/>
      </geometry>
    </collision>
    <!-- Model inertia as box with <size>0.078 0.03 0.03</size> -->
    <inertial>
      <mass value="0.3"/>
      <inertia ixx="0.0000450" ixy="0" ixz="0" iyy="0.0001746" iyz="0" izz="0.0001746"/>
    </inertial>
  </link>
  <!-- Define a link for the optical frame.  This will match the sensor frame and
         be oriented in the camera convention. -->
  <link name="front_mid_camera_link_optical">
    </link>
  <!-- Sensor post -->
  <link name="front_mid_camera_post_link">
    <visual>
      <geometry>
        <cylinder length="0.042999999999999955" radius="0.0076"/>
      </geometry>
      <material name="front_mid_camera_post_material">
        <color rgba="0.0 0.0 0.0 1.0"/>
      </material>
    </visual>
    <collision name="front_mid_camera_post_collision">
      <geometry>
        <cylinder length="0.042999999999999955" radius="0.0076"/>
      </geometry>
    </collision>
    <inertial>
      <mass value="0.038699999999999964"/>
      <inertia ixx="6.521852999999981e-06" ixy="0" ixz="0" iyy="6.521852999999981e-06" iyz="0" izz="1.117655999999999e-06"/>
    </inertial>
  </link>
  <!-- Sensor post arm -->
  <link name="front_mid_camera_post_arm_link">
    <visual name="front_mid_camera_post_arm_visual">
      <origin rpy="-1.0471975511965976 0 -1.5707963267948966" xyz="-0.038 0 -0.003"/>
      <geometry>
        <mesh filename="package://vrx_gazebo/models/sensor_post/mesh/sensor_post_arm.dae"/>
      </geometry>
    </visual>
    <collision name="front_mid_camera_post_arm_collision">
      <origin rpy="-1.2042771838760873 0 -1.5707963267948966" xyz="0 0 0"/>
      <geometry>
        <cylinder length="0.065" radius="0.008"/>
      </geometry>
    </collision>
    <inertial>
      <origin rpy="-1.2042771838760873 0 -1.5707963267948966" xyz="0 0 0"/>
      <mass value="0.1"/>
      <inertia ixx="0.00003680833" ixy="0" ixz="0" iyy="0.00003680833" iyz="0" izz="0.00000320000"/>
    </inertial>
  </link>
  <joint name="base_to_front_mid_camera_post_joint" type="fixed">
    <origin rpy="0 0 0.0" xyz="0.95 0.0 0.6515"/>
    <parent link="base_link"/>
    <child link="front_mid_camera_post_link"/>
  </joint>
  <!-- Sensor post to sensor post arm joint -->
  <joint name="front_mid_camera_post_to_front_mid_camera_post_arm_joint" type="fixed">
    <origin rpy="0 0 0" xyz="0.03 0 0.021499999999999988"/>
    <parent link="front_mid_camera_post_link"/>
    <child link="front_mid_camera_post_arm_link"/>
  </joint>
  <!-- Sensor post arm to camera joint -->
  <joint name="front_mid_camera_post_arm_to_front_mid_camera_joint" type="fixed">
    <origin rpy="0.0 0.0 0.0" xyz="0.02 0 0.027"/>
    <parent link="front_mid_camera_post_arm_link"/>
    <child link="front_mid_camera_link"/>
  </joint>
  <!-- Camera to optical frame joint.  This is oriented to convert between ENU
         and camera conventions -->
  <joint name="front_mid_camera_to_front_mid_camera_link_optical_joint" type="fixed">
    <origin rpy="-1.5707963267948966 0 -1.5707963267948966" xyz="0 0 0"/>
    <parent link="front_mid_camera_link"/>
    <child link="front_mid_camera_link_optical"/>
  </joint>
  <!-- Gazebo camera setup -->
  <gazebo reference="front_mid_camera_link">
    <sensor name="front_mid_camera_sensor" type="camera">
      <update_rate>30.0</update_rate>
      <visualize>true</visualize>
      <camera name="front_mid_camera_camera">
        <horizontal_fov>1.3962634</horizontal_fov>
        <image>
          <width>1280</width>
          <height>720</height>
          <format>R8G8B8</format>
        </image>
        <clip>
          <near>0.05</near>
          <far>300</far>
        </clip>
        <noise>
          <type>gaussian</type>
          <!-- Noise is sampled independently per pixel on each frame.
                 That pixel's noise value is added to each of its color
                 channels, which at that point lie in the range [0,1]. -->
          <mean>0.0</mean>
          <stddev>0.007</stddev>
        </noise>
      </camera>
      <plugin filename="libgazebo_ros_camera.so" name="camera_plugin_front_mid_camera">
        <alwaysOn>true</alwaysOn>
        <updateRate>0.0</updateRate>
        <cameraName>sensors/cameras/front_mid_camera</cameraName>
        <imageTopicName>image_raw</imageTopicName>
        <cameraInfoTopicName>camera_info</cameraInfoTopicName>
        <frameName>front_mid_camera_link_optical</frameName>
        <hackBaseline>0.07</hackBaseline>
        <distortionK1>0.0</distortionK1>
        <distortionK2>0.0</distortionK2>
        <distortionK3>0.0</distortionK3>
        <distortionT1>0.0</distortionT1>
        <distortionT2>0.0</distortionT2>
      </plugin>
    </sensor>
  </gazebo>
  <!-- Set color of post -->
  <gazebo reference="front_mid_camera_post_link">
    <material>Gazebo/Black</material>
  </gazebo>
  <link name="gps_left_link">
    <visual name="gps_left_visual">
      <geometry>
        <mesh filename="package://wamv_gazebo/models/gps/mesh/gps.dae" scale="0.25 0.25 0.25"/>
      </geometry>
    </visual>
    <collision name="gps_left_collision_base">
      <origin rpy="0 0 0" xyz="0 0 0.025"/>
      <geometry>
        <cylinder length="0.025" radius="0.0075"/>
      </geometry>
    </collision>
    <collision name="gps_left_collision_antenna">
      <origin rpy="0 0 0" xyz="0 0 0.03"/>
      <geometry>
        <cylinder length="0.04" radius="0.05"/>
      </geometry>
    </collision>
    <inertial>
      <mass value="1"/>
      <inertia ixx="0.006458" ixy="0.0" ixz="0.0" iyy="0.006458" iyz="0.0" izz="0.01125"/>
    </inertial>
  </link>
  <joint name="gps_left_joint" type="fixed">
    <axis xyz="0 0 1"/>
    <limit effort="1000.0" lower="0.0" upper="0" velocity="0"/>
    <origin rpy="0.0 0.0 0.0" xyz="0.0 0.18 0.83"/>
    <parent link="base_link"/>
    <child link="gps_left_link"/>
  </joint>
  <gazebo>
    <plugin filename="libhector_gazebo_ros_gps.so" name="gps_plugin_gps_left">
      <updateRate>15</updateRate>
      <alwaysOn>true</alwaysOn>
      <bodyName>gps_left_link</bodyName>
      <frameId>gps_left_link</frameId>
      <topicName>gps_left/gps/fix</topicName>
      <velocityTopicName>gps_left/gps/fix_velocity</velocityTopicName>
      <useWorldSphericalCoordinates>true</useWorldSphericalCoordinates>
      <referenceLatitude>21.30996</referenceLatitude>
      <referenceLongitude>-157.8901</referenceLongitude>
      <referenceAltitude>1.3</referenceAltitude>
      <referenceHeading>90</referenceHeading>
      <offset>0.0 0.0 0.0</offset>
      <drift>0.0 0.0 0.0</drift>
      <gaussianNoise>0 0 0</gaussianNoise>
      <velocityOffset>0.0 0.0 0.0</velocityOffset>
      <velocityDrift>0.0 0.0 0.0</velocityDrift>
      <velocityGaussianNoise>0.0 0.0 0.0</velocityGaussianNoise>
    </plugin>
  </gazebo>
  <link name="gps_right_link">
    <visual name="gps_right_visual">
      <geometry>
        <mesh filename="package://wamv_gazebo/models/gps/mesh/gps.dae" scale="0.25 0.25 0.25"/>
      </geometry>
    </visual>
    <collision name="gps_right_collision_base">
      <origin rpy="0 0 0" xyz="0 0 0.025"/>
      <geometry>
        <cylinder length="0.025" radius="0.0075"/>
      </geometry>
    </collision>
    <collision name="gps_right_collision_antenna">
      <origin rpy="0 0 0" xyz="0 0 0.03"/>
      <geometry>
        <cylinder length="0.04" radius="0.05"/>
      </geometry>
    </collision>
    <inertial>
      <mass value="1"/>
      <inertia ixx="0.006458" ixy="0.0" ixz="0.0" iyy="0.006458" iyz="0.0" izz="0.01125"/>
    </inertial>
  </link>
  <joint name="gps_right_joint" type="fixed">
    <axis xyz="0 0 1"/>
    <limit effort="1000.0" lower="0.0" upper="0" velocity="0"/>
    <origin rpy="0.0 0.0 0.0" xyz="0.0 -0.18 0.83"/>
    <parent link="base_link"/>
    <child link="gps_right_link"/>
  </joint>
  <gazebo>
    <plugin filename="libhector_gazebo_ros_gps.so" name="gps_plugin_gps_right">
      <updateRate>15</updateRate>
      <alwaysOn>true</alwaysOn>
      <bodyName>gps_right_link</bodyName>
      <frameId>gps_right_link</frameId>
      <topicName>gps_right/gps/fix</topicName>
      <velocityTopicName>gps_right/gps/fix_velocity</velocityTopicName>
      <useWorldSphericalCoordinates>true</useWorldSphericalCoordinates>
      <referenceLatitude>21.30996</referenceLatitude>
      <referenceLongitude>-157.8901</referenceLongitude>
      <referenceAltitude>1.3</referenceAltitude>
      <referenceHeading>90</referenceHeading>
      <offset>0.0 0.0 0.0</offset>
      <drift>0.0 0.0 0.0</drift>
      <gaussianNoise>0 0 0</gaussianNoise>
      <velocityOffset>0.0 0.0 0.0</velocityOffset>
      <velocityDrift>0.0 0.0 0.0</velocityDrift>
      <velocityGaussianNoise>0.0 0.0 0.0</velocityGaussianNoise>
    </plugin>
  </gazebo>
  <link name="imu_wamv_link">
    <visual name="imu_wamv_visual">
      &gt;
        
      <geometry>
        <box size="0.05 0.025 0.005"/>
      </geometry>
      <material name="imu_wamv_visual_material">
        <color rgba="1.0 0.0 00 1.0"/>
      </material>
    </visual>
    <inertial>
      <mass value="0.1"/>
      <inertia ixx="0.000083" ixy="0.0" ixz="0.0" iyy="0.000083" iyz="0.0" izz="0.0125"/>
    </inertial>
  </link>
  <joint name="imu_wamv_joint" type="fixed">
    <origin rpy="0.0 0.0 0.0" xyz="0.0 0.0 0.63"/>
    <parent link="base_link"/>
    <child link="imu_wamv_link"/>
  </joint>
  <gazebo>
    <plugin filename="libhector_gazebo_ros_imu.so" name="imu_plugin_imu_wamv">
      <updateRate>30</updateRate>
      <bodyName>imu_wamv_link</bodyName>
      <topicName>sensors/imu/imu/data</topicName>
      <serviceName>sensors/imu_service</serviceName>
      <!-- Manually prepend namespace to tf frame. -->
      <frameId>imu_wamv_link</frameId>
      <alwaysOn>true</alwaysOn>
      <accelOffset>0.0 0.0 0.0</accelOffset>
      <accelDrift>0.0 0.0 0.0</accelDrift>
      <accelDriftFrequency>0.00027 0.00027 0.000027</accelDriftFrequency>
      <accelGaussianNoise>0.0 0.0 0.0</accelGaussianNoise>
      <rateOffset>0.0 0.0 0.0</rateOffset>
      <rateDrift>0.0 0.0 0.0</rateDrift>
      <rateDriftFrequency>0.00027 0.00027 0.000027</rateDriftFrequency>
      <rateGaussianNoise>0.0 0.0 0.0</rateGaussianNoise>
      <yawOffset>0.0</yawOffset>
      <yawDrift>0.0</yawDrift>
      <yawDriftFrequency>0.00027</yawDriftFrequency>
      <yawGaussianNoise>0.0</yawGaussianNoise>
    </plugin>
  </gazebo>
  <!-- 3d lidar sensor -->
  <link name="lidar_wamv_link">
    <visual name="lidar_wamv_visual">
      <origin rpy="0 0 0" xyz="0 0 -0.035"/>
      <geometry>
        <mesh filename="package://vrx_gazebo/models/3d_lidar/mesh/3d_lidar.dae"/>
      </geometry>
    </visual>
    <collision name="lidar_wamv_collision">
      <geometry>
        <cylinder length="0.075" radius="0.055"/>
      </geometry>
    </collision>
    <inertial>
      <mass value="1"/>
      <inertia ixx="0.00109375" ixy="0" ixz="0" iyy="0.00109375" iyz="0" izz="0.00125"/>
    </inertial>
  </link>
  <!-- Sensor post -->
  <link name="lidar_wamv_post_link">
    <visual>
      <geometry>
        <cylinder length="0.32" radius="0.0076"/>
      </geometry>
      <material name="lidar_wamv_post_material">
        <color rgba="0.0 0.0 0.0 1.0"/>
      </material>
    </visual>
    <collision name="lidar_wamv_post_collision">
      <geometry>
        <cylinder length="0.32" radius="0.0076"/>
      </geometry>
    </collision>
    <inertial>
      <mass value="0.28800000000000003"/>
      <inertia ixx="0.0024617587200000007" ixy="0" ixz="0" iyy="0.0024617587200000007" iyz="0" izz="8.317440000000002e-06"/>
    </inertial>
  </link>
  <!-- Sensor post arm -->
  <link name="lidar_wamv_post_arm_link">
    <visual name="lidar_wamv_post_arm_visual">
      <origin rpy="-1.0471975511965976 0 -1.5707963267948966" xyz="-0.038 0 -0.003"/>
      <geometry>
        <mesh filename="package://vrx_gazebo/models/sensor_post/mesh/sensor_post_arm.dae"/>
      </geometry>
    </visual>
    <collision name="lidar_wamv_post_arm_collision">
      <origin rpy="-1.2042771838760873 0 -1.5707963267948966" xyz="0 0 0"/>
      <geometry>
        <cylinder length="0.065" radius="0.008"/>
      </geometry>
    </collision>
    <inertial>
      <origin rpy="-1.2042771838760873 0 -1.5707963267948966" xyz="0 0 0"/>
      <mass value="0.1"/>
      <inertia ixx="0.00003680833" ixy="0" ixz="0" iyy="0.00003680833" iyz="0" izz="0.00000320000"/>
    </inertial>
  </link>
  <joint name="base_to_lidar_wamv_post_joint" type="fixed">
    <origin rpy="0 0 0.0" xyz="-0.07 0.0 0.79"/>
    <parent link="base_link"/>
    <child link="lidar_wamv_post_link"/>
  </joint>
  <!-- Sensor post to sensor post arm joint -->
  <joint name="lidar_wamv_post_to_lidar_wamv_post_arm_joint" type="fixed">
    <origin rpy="0 0 0" xyz="0.03 0 0.15999999999999998"/>
    <parent link="lidar_wamv_post_link"/>
    <child link="lidar_wamv_post_arm_link"/>
  </joint>
  <!-- Sensor post arm to lidar joint -->
  <joint name="lidar_wamv_post_arm_to_lidar_wamv_joint" type="fixed">
    <origin rpy="0.0 0 0.0" xyz="0.04 0 0.7"/>
    <parent link="lidar_wamv_post_arm_link"/>
    <child link="lidar_wamv_link"/>
  </joint>
  <gazebo reference="lidar_wamv_link">
    <sensor name="lidar_wamv_sensor" type="gpu_ray">
      <update_rate>15</update_rate>
      <ray>
        <scan>
          <horizontal>
            <samples>20000.0</samples>
            <resolution>0.018</resolution>
            <min_angle>-3.141592653589793</min_angle>
            <max_angle>3.141592653589793</max_angle>
          </horizontal>
          <vertical>
            <samples>32</samples>
            <resolution>1.875</resolution>
            <min_angle>-0.2617993877991494</min_angle>
            <max_angle>0.2617993877991494</max_angle>
          </vertical>
        </scan>
        <range>
          <min>0.1</min>
          <max>130</max>
        </range>
        <noise>
          <type>gaussian</type>
          <mean>0.0</mean>
          <stddev>0.01</stddev>
        </noise>
      </ray>
      <plugin filename="libgazebo_ros_velodyne_gpu_laser.so" name="lidar_wamv_plugin">
        <topicName>sensors/lidars/lidar_points</topicName>
        <frameName>lidar_wamv_link</frameName>
        <min_intensity>0</min_intensity>
      </plugin>
    </sensor>
  </gazebo>
  <!-- Set color of post -->
  <gazebo reference="lidar_wamv_post_link">
    <material>Gazebo/Black</material>
  </gazebo>
  <!--specs for 16 beam lidar are implemented by default.
          See wamv_3d_lidar for those-->
  <link name="pinger">
    <visual>
      <origin rpy="0 0 0" xyz="0 0 0"/>
      <geometry>
        <box size="0.1 0.1 0.1"/>
      </geometry>
    </visual>
    <collision name="pinger_collision">
      <origin rpy="0 0 0" xyz="0 0 0"/>
      <geometry>
        <box size="0.1 0.1 0.1"/>
      </geometry>
    </collision>
  </link>
  <joint name="pinger_pinger_joint" type="fixed">
    <origin rpy="0 0 0" xyz="0.5 0 -0.5"/>
    <parent link="base_link"/>
    <child link="pinger"/>
  </joint>
  <gazebo>
    <plugin filename="libusv_gazebo_acoustic_pinger_plugin.so" name="pinger_plugin">
      <frameId>pinger</frameId>
      <topicName>sensors/pingers/pinger/range_bearing</topicName>
      <setPositionTopicName>sensors/pingers/pinger/set_pinger_position</setPositionTopicName>
      <rangeNoise>
        <noise>
          <type>gaussian</type>
          <mean>0.0</mean>
          <stddev>3.0</stddev>
        </noise>
      </rangeNoise>
      <bearingNoise>
        <noise>
          <type>gaussian</type>
          <mean>0.0</mean>
          <stddev>0.01</stddev>
        </noise>
      </bearingNoise>
      <elevationNoise>
        <noise>
          <type>gaussian</type>
          <mean>0.0</mean>
          <stddev>0.01</stddev>
        </noise>
      </elevationNoise>
    </plugin>
  </gazebo>
  <link name="cpu_cases_link">
    <visual name="cpu_cases_visual">
      <origin rpy="0 0 0" xyz="0.073 0 -0.82"/>
      <geometry>
        <mesh filename="package://vrx_gazebo/models/cpu_cases/mesh/cpu_cases.dae" scale="0.45 0.45 0.45"/>
      </geometry>
    </visual>
    <collision name="cpu_case_1_collision">
      <origin rpy="0 0 0" xyz="0.119 0 -0.13"/>
      <geometry>
        <box size="0.28 0.4 0.21"/>
      </geometry>
    </collision>
    <collision name="cpu_case_2_collision">
      <origin rpy="0 0 0" xyz="-0.1 0 -0.18"/>
      <geometry>
        <box size="0.2 0.3 0.15"/>
      </geometry>
    </collision>
    <inertial>
      <mass value="20"/>
      <inertia ixx="1.51633333333333" ixy="0" ixz="0" iyy="1.93633333333333" iyz="0" izz="2.71633333333333"/>
    </inertial>
  </link>
  <joint name="chasis_cpu_cases_joint" type="fixed">
    <origin rpy="0 0 0" xyz="0 0 0.845"/>
    <parent link="base_link"/>
    <child link="cpu_cases_link"/>
  </joint>
</robot>
